2020-11-14 19:18:20,697 ERROR: Exception on /index [GET] [in /home/amboss/microblog/venv/lib/python3.8/site-packages/flask/app.py:1891]
Traceback (most recent call last):
  File "/home/amboss/microblog/venv/lib/python3.8/site-packages/flask/app.py", line 2447, in wsgi_app
    response = self.full_dispatch_request()
  File "/home/amboss/microblog/venv/lib/python3.8/site-packages/flask/app.py", line 1952, in full_dispatch_request
    rv = self.handle_user_exception(e)
  File "/home/amboss/microblog/venv/lib/python3.8/site-packages/flask/app.py", line 1821, in handle_user_exception
    reraise(exc_type, exc_value, tb)
  File "/home/amboss/microblog/venv/lib/python3.8/site-packages/flask/_compat.py", line 39, in reraise
    raise value
  File "/home/amboss/microblog/venv/lib/python3.8/site-packages/flask/app.py", line 1950, in full_dispatch_request
    rv = self.dispatch_request()
  File "/home/amboss/microblog/venv/lib/python3.8/site-packages/flask/app.py", line 1936, in dispatch_request
    return self.view_functions[rule.endpoint](**req.view_args)
  File "/home/amboss/microblog/venv/lib/python3.8/site-packages/flask_login/utils.py", line 272, in decorated_view
    return func(*args, **kwargs)
  File "/home/amboss/microblog/app/routes.py", line 34, in index
    return render_template('index.html', title='Home', form=form,
  File "/home/amboss/microblog/venv/lib/python3.8/site-packages/flask/templating.py", line 137, in render_template
    return _render(
  File "/home/amboss/microblog/venv/lib/python3.8/site-packages/flask/templating.py", line 120, in _render
    rv = template.render(context)
  File "/home/amboss/microblog/venv/lib/python3.8/site-packages/jinja2/environment.py", line 1090, in render
    self.environment.handle_exception()
  File "/home/amboss/microblog/venv/lib/python3.8/site-packages/jinja2/environment.py", line 832, in handle_exception
    reraise(*rewrite_traceback_stack(source=source))
  File "/home/amboss/microblog/venv/lib/python3.8/site-packages/jinja2/_compat.py", line 28, in reraise
    raise value.with_traceback(tb)
  File "/home/amboss/microblog/app/templates/index.html", line 1, in top-level template code
    {% extends "base.html" %}
  File "/home/amboss/microblog/app/templates/base.html", line 1, in top-level template code
    {% extends 'bootstrap/base.html' %}
  File "/home/amboss/microblog/venv/lib/python3.8/site-packages/flask_bootstrap/templates/bootstrap/base.html", line 1, in top-level template code
    {% block doc -%}
  File "/home/amboss/microblog/venv/lib/python3.8/site-packages/flask_bootstrap/templates/bootstrap/base.html", line 4, in block "doc"
    {%- block html %}
  File "/home/amboss/microblog/venv/lib/python3.8/site-packages/flask_bootstrap/templates/bootstrap/base.html", line 20, in block "html"
    {% block body -%}
  File "/home/amboss/microblog/venv/lib/python3.8/site-packages/flask_bootstrap/templates/bootstrap/base.html", line 21, in block "body"
    {% block navbar %}
  File "/home/amboss/microblog/app/templates/base.html", line 21, in block "navbar"
    <li><a href="{{ url_for('index') }}">{{ _('Home') }}</a></li>
jinja2.exceptions.UndefinedError: '_' is undefined
2020-11-14 19:19:02,395 INFO: Microblog startup [in /home/amboss/microblog/app/__init__.py:35]
2020-11-14 19:45:55,184 INFO: Microblog startup [in /home/amboss/microblog/app/__init__.py:35]
2020-11-14 19:49:11,439 INFO: Microblog startup [in /home/amboss/microblog/app/__init__.py:35]
2020-11-14 19:51:22,278 INFO: Microblog startup [in /home/amboss/microblog/app/__init__.py:35]
2020-11-14 19:52:46,961 INFO: Microblog startup [in /home/amboss/microblog/app/__init__.py:35]
2020-11-14 19:54:08,100 INFO: Microblog startup [in /home/amboss/microblog/app/__init__.py:35]
2020-11-14 19:54:22,400 ERROR: Exception on /reset_password_request [POST] [in /home/amboss/microblog/venv/lib/python3.8/site-packages/flask/app.py:1891]
Traceback (most recent call last):
  File "/home/amboss/microblog/venv/lib/python3.8/site-packages/flask/app.py", line 2447, in wsgi_app
    response = self.full_dispatch_request()
  File "/home/amboss/microblog/venv/lib/python3.8/site-packages/flask/app.py", line 1952, in full_dispatch_request
    rv = self.handle_user_exception(e)
  File "/home/amboss/microblog/venv/lib/python3.8/site-packages/flask/app.py", line 1821, in handle_user_exception
    reraise(exc_type, exc_value, tb)
  File "/home/amboss/microblog/venv/lib/python3.8/site-packages/flask/_compat.py", line 39, in reraise
    raise value
  File "/home/amboss/microblog/venv/lib/python3.8/site-packages/flask/app.py", line 1950, in full_dispatch_request
    rv = self.dispatch_request()
  File "/home/amboss/microblog/venv/lib/python3.8/site-packages/flask/app.py", line 1936, in dispatch_request
    return self.view_functions[rule.endpoint](**req.view_args)
  File "/home/amboss/microblog/app/routes.py", line 166, in reset_password_request
    send_password_reset_email(user)
  File "/home/amboss/microblog/app/email.py", line 8, in send_password_reset_email
    send_email('[Microblog] Reset Your Password',
  File "/home/amboss/microblog/app/email.py", line 24, in send_email
    Thread(target=send_async_email, args=(app, msg).start())
AttributeError: 'tuple' object has no attribute 'start'
2020-11-14 19:56:23,837 ERROR: Exception on /reset_password_request [POST] [in /home/amboss/microblog/venv/lib/python3.8/site-packages/flask/app.py:1891]
Traceback (most recent call last):
  File "/home/amboss/microblog/venv/lib/python3.8/site-packages/flask/app.py", line 2447, in wsgi_app
    response = self.full_dispatch_request()
  File "/home/amboss/microblog/venv/lib/python3.8/site-packages/flask/app.py", line 1952, in full_dispatch_request
    rv = self.handle_user_exception(e)
  File "/home/amboss/microblog/venv/lib/python3.8/site-packages/flask/app.py", line 1821, in handle_user_exception
    reraise(exc_type, exc_value, tb)
  File "/home/amboss/microblog/venv/lib/python3.8/site-packages/flask/_compat.py", line 39, in reraise
    raise value
  File "/home/amboss/microblog/venv/lib/python3.8/site-packages/flask/app.py", line 1950, in full_dispatch_request
    rv = self.dispatch_request()
  File "/home/amboss/microblog/venv/lib/python3.8/site-packages/flask/app.py", line 1936, in dispatch_request
    return self.view_functions[rule.endpoint](**req.view_args)
  File "/home/amboss/microblog/app/routes.py", line 166, in reset_password_request
    send_password_reset_email(user)
  File "/home/amboss/microblog/app/email.py", line 8, in send_password_reset_email
    send_email('[Microblog] Reset Your Password',
  File "/home/amboss/microblog/app/email.py", line 24, in send_email
    Thread(target=send_async_email, args=(app, msg).start())
AttributeError: 'tuple' object has no attribute 'start'
2020-11-14 19:56:55,754 INFO: Microblog startup [in /home/amboss/microblog/app/__init__.py:35]
2020-11-14 19:57:17,244 ERROR: Exception on /reset_password_request [POST] [in /home/amboss/microblog/venv/lib/python3.8/site-packages/flask/app.py:1891]
Traceback (most recent call last):
  File "/home/amboss/microblog/venv/lib/python3.8/site-packages/flask/app.py", line 2447, in wsgi_app
    response = self.full_dispatch_request()
  File "/home/amboss/microblog/venv/lib/python3.8/site-packages/flask/app.py", line 1952, in full_dispatch_request
    rv = self.handle_user_exception(e)
  File "/home/amboss/microblog/venv/lib/python3.8/site-packages/flask/app.py", line 1821, in handle_user_exception
    reraise(exc_type, exc_value, tb)
  File "/home/amboss/microblog/venv/lib/python3.8/site-packages/flask/_compat.py", line 39, in reraise
    raise value
  File "/home/amboss/microblog/venv/lib/python3.8/site-packages/flask/app.py", line 1950, in full_dispatch_request
    rv = self.dispatch_request()
  File "/home/amboss/microblog/venv/lib/python3.8/site-packages/flask/app.py", line 1936, in dispatch_request
    return self.view_functions[rule.endpoint](**req.view_args)
  File "/home/amboss/microblog/app/routes.py", line 166, in reset_password_request
    send_password_reset_email(user)
  File "/home/amboss/microblog/app/email.py", line 8, in send_password_reset_email
    send_email('[Microblog] Reset Your Password',
  File "/home/amboss/microblog/app/email.py", line 24, in send_email
    Thread(target=send_async_email, args=(app, msg).start())
AttributeError: 'tuple' object has no attribute 'start'
2020-11-14 20:00:11,803 INFO: Microblog startup [in /home/amboss/microblog/app/__init__.py:35]
2020-11-14 20:00:21,212 ERROR: Exception on /reset_password_request [POST] [in /home/amboss/microblog/venv/lib/python3.8/site-packages/flask/app.py:1891]
Traceback (most recent call last):
  File "/home/amboss/microblog/venv/lib/python3.8/site-packages/flask/app.py", line 2447, in wsgi_app
    response = self.full_dispatch_request()
  File "/home/amboss/microblog/venv/lib/python3.8/site-packages/flask/app.py", line 1952, in full_dispatch_request
    rv = self.handle_user_exception(e)
  File "/home/amboss/microblog/venv/lib/python3.8/site-packages/flask/app.py", line 1821, in handle_user_exception
    reraise(exc_type, exc_value, tb)
  File "/home/amboss/microblog/venv/lib/python3.8/site-packages/flask/_compat.py", line 39, in reraise
    raise value
  File "/home/amboss/microblog/venv/lib/python3.8/site-packages/flask/app.py", line 1950, in full_dispatch_request
    rv = self.dispatch_request()
  File "/home/amboss/microblog/venv/lib/python3.8/site-packages/flask/app.py", line 1936, in dispatch_request
    return self.view_functions[rule.endpoint](**req.view_args)
  File "/home/amboss/microblog/app/routes.py", line 166, in reset_password_request
    send_password_reset_email(user)
  File "/home/amboss/microblog/app/email.py", line 9, in send_password_reset_email
    send_email('[Microblog] Reset Your Password',
  File "/home/amboss/microblog/app/email.py", line 25, in send_email
    Thread(target=send_async_email, args=(app, msg).start())
AttributeError: 'tuple' object has no attribute 'start'
2020-11-14 20:02:28,288 INFO: Microblog startup [in /home/amboss/microblog/app/__init__.py:35]
