2020-11-11 12:35:55,467 ERROR: Exception on /index [GET] [in /home/amboss/microblog/venv/lib/python3.8/site-packages/flask/app.py:1891]
Traceback (most recent call last):
  File "/home/amboss/microblog/venv/lib/python3.8/site-packages/flask/app.py", line 2447, in wsgi_app
    response = self.full_dispatch_request()
  File "/home/amboss/microblog/venv/lib/python3.8/site-packages/flask/app.py", line 1952, in full_dispatch_request
    rv = self.handle_user_exception(e)
  File "/home/amboss/microblog/venv/lib/python3.8/site-packages/flask/app.py", line 1821, in handle_user_exception
    reraise(exc_type, exc_value, tb)
  File "/home/amboss/microblog/venv/lib/python3.8/site-packages/flask/_compat.py", line 39, in reraise
    raise value
  File "/home/amboss/microblog/venv/lib/python3.8/site-packages/flask/app.py", line 1950, in full_dispatch_request
    rv = self.dispatch_request()
  File "/home/amboss/microblog/venv/lib/python3.8/site-packages/flask/app.py", line 1936, in dispatch_request
    return self.view_functions[rule.endpoint](**req.view_args)
  File "/home/amboss/microblog/venv/lib/python3.8/site-packages/flask_login/utils.py", line 272, in decorated_view
    return func(*args, **kwargs)
  File "/home/amboss/microblog/app/routes.py", line 27, in index
    posts = current_user.followed_posts().paginate(page, app.config['POSTS_PER_PAGE'], False)
KeyError: 'POSTS_PER_PAGE'
2020-11-11 12:41:32,705 INFO: Microblog startup [in /home/amboss/microblog/app/__init__.py:32]
2020-11-11 12:41:52,742 ERROR: Exception on /index [GET] [in /home/amboss/microblog/venv/lib/python3.8/site-packages/flask/app.py:1891]
Traceback (most recent call last):
  File "/home/amboss/microblog/venv/lib/python3.8/site-packages/flask/app.py", line 2447, in wsgi_app
    response = self.full_dispatch_request()
  File "/home/amboss/microblog/venv/lib/python3.8/site-packages/flask/app.py", line 1952, in full_dispatch_request
    rv = self.handle_user_exception(e)
  File "/home/amboss/microblog/venv/lib/python3.8/site-packages/flask/app.py", line 1821, in handle_user_exception
    reraise(exc_type, exc_value, tb)
  File "/home/amboss/microblog/venv/lib/python3.8/site-packages/flask/_compat.py", line 39, in reraise
    raise value
  File "/home/amboss/microblog/venv/lib/python3.8/site-packages/flask/app.py", line 1950, in full_dispatch_request
    rv = self.dispatch_request()
  File "/home/amboss/microblog/venv/lib/python3.8/site-packages/flask/app.py", line 1936, in dispatch_request
    return self.view_functions[rule.endpoint](**req.view_args)
  File "/home/amboss/microblog/venv/lib/python3.8/site-packages/flask_login/utils.py", line 272, in decorated_view
    return func(*args, **kwargs)
  File "/home/amboss/microblog/app/routes.py", line 27, in index
    posts = current_user.followed_posts().paginate(page, app.config['POSTS_PER_PAGE'], False)
KeyError: 'POSTS_PER_PAGE'
2020-11-11 12:44:01,320 INFO: Microblog startup [in /home/amboss/microblog/app/__init__.py:32]
2020-11-11 12:47:14,116 INFO: Microblog startup [in /home/amboss/microblog/app/__init__.py:32]
2020-11-11 12:49:03,913 INFO: Microblog startup [in /home/amboss/microblog/app/__init__.py:32]
2020-11-11 12:57:50,321 INFO: Microblog startup [in /home/amboss/microblog/app/__init__.py:32]
2020-11-11 13:06:33,961 INFO: Microblog startup [in /home/amboss/microblog/app/__init__.py:32]
2020-11-11 13:07:12,262 INFO: Microblog startup [in /home/amboss/microblog/app/__init__.py:32]
2020-11-11 13:16:53,084 INFO: Microblog startup [in /home/amboss/microblog/app/__init__.py:32]
2020-11-13 10:12:53,086 INFO: Microblog startup [in /home/amboss/microblog/app/__init__.py:32]
2020-11-13 10:13:04,841 INFO: Microblog startup [in /home/amboss/microblog/app/__init__.py:32]
2020-11-13 10:13:32,020 INFO: Microblog startup [in /home/amboss/microblog/app/__init__.py:32]
2020-11-13 10:14:02,546 ERROR: Exception on /edit_profile [POST] [in /home/amboss/microblog/venv/lib/python3.8/site-packages/flask/app.py:1891]
Traceback (most recent call last):
  File "/home/amboss/microblog/venv/lib/python3.8/site-packages/sqlalchemy/engine/base.py", line 1276, in _execute_context
    self.dialect.do_execute(
  File "/home/amboss/microblog/venv/lib/python3.8/site-packages/sqlalchemy/engine/default.py", line 593, in do_execute
    cursor.execute(statement, parameters)
sqlite3.IntegrityError: UNIQUE constraint failed: user.username

The above exception was the direct cause of the following exception:

Traceback (most recent call last):
  File "/home/amboss/microblog/venv/lib/python3.8/site-packages/flask/app.py", line 2447, in wsgi_app
    response = self.full_dispatch_request()
  File "/home/amboss/microblog/venv/lib/python3.8/site-packages/flask/app.py", line 1952, in full_dispatch_request
    rv = self.handle_user_exception(e)
  File "/home/amboss/microblog/venv/lib/python3.8/site-packages/flask/app.py", line 1821, in handle_user_exception
    reraise(exc_type, exc_value, tb)
  File "/home/amboss/microblog/venv/lib/python3.8/site-packages/flask/_compat.py", line 39, in reraise
    raise value
  File "/home/amboss/microblog/venv/lib/python3.8/site-packages/flask/app.py", line 1950, in full_dispatch_request
    rv = self.dispatch_request()
  File "/home/amboss/microblog/venv/lib/python3.8/site-packages/flask/app.py", line 1936, in dispatch_request
    return self.view_functions[rule.endpoint](**req.view_args)
  File "/home/amboss/microblog/venv/lib/python3.8/site-packages/flask_login/utils.py", line 272, in decorated_view
    return func(*args, **kwargs)
  File "/home/amboss/microblog/app/routes.py", line 95, in edit_profile
    db.session.commit()
  File "/home/amboss/microblog/venv/lib/python3.8/site-packages/sqlalchemy/orm/scoping.py", line 163, in do
    return getattr(self.registry(), name)(*args, **kwargs)
  File "/home/amboss/microblog/venv/lib/python3.8/site-packages/sqlalchemy/orm/session.py", line 1042, in commit
    self.transaction.commit()
  File "/home/amboss/microblog/venv/lib/python3.8/site-packages/sqlalchemy/orm/session.py", line 504, in commit
    self._prepare_impl()
  File "/home/amboss/microblog/venv/lib/python3.8/site-packages/sqlalchemy/orm/session.py", line 483, in _prepare_impl
    self.session.flush()
  File "/home/amboss/microblog/venv/lib/python3.8/site-packages/sqlalchemy/orm/session.py", line 2536, in flush
    self._flush(objects)
  File "/home/amboss/microblog/venv/lib/python3.8/site-packages/sqlalchemy/orm/session.py", line 2678, in _flush
    transaction.rollback(_capture_exception=True)
  File "/home/amboss/microblog/venv/lib/python3.8/site-packages/sqlalchemy/util/langhelpers.py", line 68, in __exit__
    compat.raise_(
  File "/home/amboss/microblog/venv/lib/python3.8/site-packages/sqlalchemy/util/compat.py", line 182, in raise_
    raise exception
  File "/home/amboss/microblog/venv/lib/python3.8/site-packages/sqlalchemy/orm/session.py", line 2638, in _flush
    flush_context.execute()
  File "/home/amboss/microblog/venv/lib/python3.8/site-packages/sqlalchemy/orm/unitofwork.py", line 422, in execute
    rec.execute(self)
  File "/home/amboss/microblog/venv/lib/python3.8/site-packages/sqlalchemy/orm/unitofwork.py", line 586, in execute
    persistence.save_obj(
  File "/home/amboss/microblog/venv/lib/python3.8/site-packages/sqlalchemy/orm/persistence.py", line 230, in save_obj
    _emit_update_statements(
  File "/home/amboss/microblog/venv/lib/python3.8/site-packages/sqlalchemy/orm/persistence.py", line 994, in _emit_update_statements
    c = cached_connections[connection].execute(
  File "/home/amboss/microblog/venv/lib/python3.8/site-packages/sqlalchemy/engine/base.py", line 1011, in execute
    return meth(self, multiparams, params)
  File "/home/amboss/microblog/venv/lib/python3.8/site-packages/sqlalchemy/sql/elements.py", line 298, in _execute_on_connection
    return connection._execute_clauseelement(self, multiparams, params)
  File "/home/amboss/microblog/venv/lib/python3.8/site-packages/sqlalchemy/engine/base.py", line 1124, in _execute_clauseelement
    ret = self._execute_context(
  File "/home/amboss/microblog/venv/lib/python3.8/site-packages/sqlalchemy/engine/base.py", line 1316, in _execute_context
    self._handle_dbapi_exception(
  File "/home/amboss/microblog/venv/lib/python3.8/site-packages/sqlalchemy/engine/base.py", line 1510, in _handle_dbapi_exception
    util.raise_(
  File "/home/amboss/microblog/venv/lib/python3.8/site-packages/sqlalchemy/util/compat.py", line 182, in raise_
    raise exception
  File "/home/amboss/microblog/venv/lib/python3.8/site-packages/sqlalchemy/engine/base.py", line 1276, in _execute_context
    self.dialect.do_execute(
  File "/home/amboss/microblog/venv/lib/python3.8/site-packages/sqlalchemy/engine/default.py", line 593, in do_execute
    cursor.execute(statement, parameters)
sqlalchemy.exc.IntegrityError: (sqlite3.IntegrityError) UNIQUE constraint failed: user.username
[SQL: UPDATE user SET username=?, about_me=? WHERE user.id = ?]
[parameters: ('admin', '', 7)]
(Background on this error at: http://sqlalche.me/e/13/gkpj)
2020-11-13 10:14:33,162 INFO: Microblog startup [in /home/amboss/microblog/app/__init__.py:32]
2020-11-13 10:23:45,974 INFO: Microblog startup [in /home/amboss/microblog/app/__init__.py:34]
2020-11-13 10:30:59,000 INFO: Microblog startup [in /home/amboss/microblog/app/__init__.py:34]
2020-11-13 11:15:54,590 INFO: Microblog startup [in /home/amboss/microblog/app/__init__.py:34]
2020-11-13 11:16:03,796 INFO: Microblog startup [in /home/amboss/microblog/app/__init__.py:34]
2020-11-13 11:21:55,236 INFO: Microblog startup [in /home/amboss/microblog/app/__init__.py:34]
2020-11-13 15:17:09,946 INFO: Microblog startup [in /home/amboss/microblog/app/__init__.py:34]
2020-11-13 15:23:16,045 INFO: Microblog startup [in /home/amboss/microblog/app/__init__.py:34]
